Workbook
Name Slicer_Year: #N/A

Sheet Dashboard

Sheet Valuation-FCFF
D2: NSE: ASIANPAINT | BSE:500820
D3: 52-WEEK (HIGH: ₹ 2985.70| LOW: ₹ 2115.00 )
D4: 2649.4
D5: (as at 13 July 2026)
B6: VALUATION USING FCFF TECHNIQUE
B7: (in ₹ Cr. unless stated otherwise)
G8: Forecasts
B9: Years | G9: 27 | H9: =G9+1 -> 28 | I9: =H9+1 -> 29 | J9: =I9+1 -> 30
B11: Reported Earnings Before Interest and Tax (EBIT) | G11: =SOPL!P24 -> 6556.1789 | H11: =SOPL!Q24 -> 7139.5081 | I11: =SOPL!R24 -> 7764.2112 | J11: =SOPL!S24 -> 8433.6894 | L11: Capital Structure (A) | M11: Weightage of Capital Structure | N11: Cost of Capital (B) | O11: A*B
B12: Less: Other Non-Operating Income | G12: =-SOPL!P19 -> -836.24905 | H12: =-SOPL!Q19 -> -966.16811 | I12: =-SOPL!R19 -> -1116.2713 | J12: =-SOPL!S19 -> -1289.6944
B13: Adjusted Earnings Before Interest And Tax | G13: =SUM(G11:G12) -> 5719.9298 | H13: =SUM(H11:H12) -> 6173.34 | I13: =SUM(I11:I12) -> 6647.9399 | J13: =SUM(J11:J12) -> 7143.995 | L13: Debt | M13: 0.12 | N13: =J30 -> 0.047119396 | O13: =M13*N13 -> 0.0056543275
B14: Less: Tax | G14: =G13*-0.268 -> -1532.9412 | H14: =H13*-0.268 -> -1654.4551 | I14: =I13*-0.268 -> -1781.6479 | J14: =J13*-0.268 -> -1914.5907 | L14: Ordinary Shares | M14: 0.88 | N14: =J23+J28*J24 -> 0.12904966 | O14: =M14*N14 -> 0.1135637
B15: Add: Depreciation and Amortisation | G15: =Schedule!AG47 -> 1338.0711 | H15: =Schedule!AH47 -> 1402.9337 | I15: =Schedule!AI47 -> 1477.7125 | J15: =Schedule!AJ47 -> 1562.8011 | M15: =SUM(M13:M14) -> 1 | O15: =SUM(O13:O14) -> 0.11921803
B16: Add: Impairment expense on Goodwill & Intangible Asset | G16: 25.72 | H16: 25.72 | I16: 25.72 | J16: 25.72 | M16: WACC | N16: =O15/M15 -> 0.11921803
B17: Less: Net CapEx (PPE, Goodwill and Intangible Asset) | G17: =-(Schedule!Z11+Schedule!Z26) -> -1109.7583 | H17: =SOCF!R28 -> -1211.2055 | I17: =SOCF!S28 -> -1321.9717 | J17: =SOCF!T28 -> -1442.9098
B18: Less: Increase in Working Capital | G18: =('SOFP '!O33-'SOFP '!O61)-('SOFP '!P33-'SOFP '!P61) -> -1416.7583 | H18: =('SOFP '!P33-'SOFP '!P61)-('SOFP '!Q33-'SOFP '!Q61) -> -1635.0982 | I18: =('SOFP '!Q33-'SOFP '!Q61)-('SOFP '!R33-'SOFP '!R61) -> -1753.1762 | J18: =('SOFP '!R33-'SOFP '!R61)-('SOFP '!S33-'SOFP '!S61) -> -1889.4196 | L18: (in ₹ Cr. unless stated otherwise)
L19: PV of FCFF (FY2027E-30E) | O19: =NPV(N16,G20:J20) -> 9749.1524
B20: FREE CASH FLOW TO FIRM (FCFF) | G20: =SUM(G13:G18) -> 3024.2631 | H20: =SUM(H13:H18) -> 3101.2349 | I20: =SUM(I13:I18) -> 3294.5765 | J20: =SUM(J13:J18) -> 3485.596 | L20: Terminal Value | O20: =J20*(1+J22)/(N16-J22)/(1+N16)^4 -> 32915.787
L21: Value of Firm | O21: =SUM(O19:O20) -> 42664.939
B22: Company | D22: 5-Year Levered Beta | E22: Debt / Equity | G22: Terminal Growth | J22: =(J20/G20)^(1/3)-1 -> 0.048461503 | L22: Value of Debt | O22: ='SOFP '!O46+'SOFP '!O47 -> 2554.11
G23: Risk-free Rate | J23: 0.067 | L23: Value of Equity | O23: =O21-O22 -> 40110.829
B24: Berger Paints India | D24: 0.67 | E24: 0.07 | G24: Equity Risk Premium | J24: 0.0731
B25: Kansai Nerolac Paints | D25: 0.82 | E25: 0.05 | G25: Median Industry Levered Beta | J25: =D28 -> 0.745
B26: Akzo Nobel India | D26: 0.39 | E26: 0.01 | G26: Industry Unlevered Beta | J26: =J25*(1-E28)/((1-E28)+E28*(1-0.268)) -> 0.72295002 | L26: Unit Share Price
B27: Indigo Paints | D27: 1.23 | E27: 0.03 | G27: Tax Rate | J27: 0.268
C28: Median | D28: =MEDIAN(D24:D27) -> 0.745 | E28: =MEDIAN(E24:E27) -> 0.04 | G28: Levered Beta for Asian Paints | J28: =J26/(0.88)/((0.88+0.12*(1-0.268))) -> 0.84883257 | L28: =O23/SOPL!O54*10000000 -> 418.42412
C29: Mean | D29: =AVERAGE(D24:D27) -> 0.7775 | E29: =AVERAGE(E24:E27) -> 0.04 | G29: Kd | J29: =(Schedule!L64-Schedule!L63-Schedule!L59)/('SOFP '!O46+'SOFP '!O47) -> 0.064370759
G30: Kd*(1-T) | J30: =J29*(1-0.268) -> 0.047119396
G31: CAPM (Ke) | J31: =J23+J28*J24 -> 0.12904966
B33: Note: The valuation has been performed using the FCFF approach under the assumption that Asian Paints Limited will continue as a going concern. Forecast financial statements were prepared using historical trends, company-specific assumptions and management-consistent operating behaviour. Market-based inputs used in estimating the discount rate were obtained from the latest publicly available sources at the valuation date, while the terminal growth rate was conservatively estimated using the forecast-period FCFF CAGR to reflect the company's long-term sustainable growth prospects.
B38: Conclusion: Based on the FCFF methodology and assumptions adopted, the calculated intrinsic value indicates that the share price appears significantly higher than the estimated fundamental value. However, the market premium may reflect investor expectations regarding Asian Paints' future growth prospects, competitive positioning, brand strength and ability to generate superior returns over the long term.

Sheet Sensitivity Analysis
D2: NSE: ASIANPAINT | BSE:500820
D3: 52-WEEK (HIGH: ₹ 2985.70| LOW: ₹ 2115.00 )
D4: 2649.4
D5: (as at 13 July 2026)
B6: SENSITIVITY ANALYSIS
B7: (in ₹ Cr. unless stated otherwise)
G8: Forecasts
B9: Years | G9: 27 | H9: =G9+1 -> 28 | I9: =H9+1 -> 29 | J9: =I9+1 -> 30
B10: Operating Revenue | G10: =SOPL!O13*(1+'Sensitivity Analysis'!$D$24) -> 40921.071 | H10: =G10*(1+$D$24) -> 47059.232 | I10: =H10*(1+$D$24) -> 54118.116 | J10: =I10*(1+$D$24) -> 62235.834
B11: Earnings Before Interest and Tax (EBIT) | G11: =G10*$D$25 -> 10230.268 | H11: =H10*$D$25 -> 11764.808 | I11: =I10*$D$25 -> 13529.529 | J11: =J10*$D$25 -> 15558.958
B12: Less: Other Non-Operating Income | G12: ='Valuation-FCFF'!G12 -> -836.24905 | H12: ='Valuation-FCFF'!H12 -> -966.16811 | I12: ='Valuation-FCFF'!I12 -> -1116.2713 | J12: ='Valuation-FCFF'!J12 -> -1289.6944
B13: Less: Tax | G13: =-SUM(G11:G12)*$D$28 -> -1409.1028 | H13: =-SUM(H11:H12)*$D$28 -> -1619.796 | I13: =-SUM(I11:I12)*$D$28 -> -1861.9887 | J13: =-SUM(J11:J12)*$D$28 -> -2140.3896
B14: Add: Depreciation and Amortisation | G14: ='Valuation-FCFF'!G15 -> 1338.0711 | H14: ='Valuation-FCFF'!H15 -> 1402.9337 | I14: ='Valuation-FCFF'!I15 -> 1477.7125 | J14: ='Valuation-FCFF'!J15 -> 1562.8011
B15: Add: Impairment expense on Goodwill & Intangible Asset | G15: ='Valuation-FCFF'!G16 -> 25.72 | H15: ='Valuation-FCFF'!H16 -> 25.72 | I15: ='Valuation-FCFF'!I16 -> 25.72 | J15: ='Valuation-FCFF'!J16 -> 25.72
B16: Less: Net CapEx (PPE, Goodwill and Intangible Asset) | G16: ='Valuation-FCFF'!G17 -> -1109.7583 | H16: ='Valuation-FCFF'!H17 -> -1211.2055 | I16: ='Valuation-FCFF'!I17 -> -1321.9717 | J16: ='Valuation-FCFF'!J17 -> -1442.9098
B17: Less: Increase in Working Capital | G17: ='Valuation-FCFF'!G18 -> -1416.7583 | H17: ='Valuation-FCFF'!H18 -> -1635.0982 | I17: ='Valuation-FCFF'!I18 -> -1753.1762 | J17: ='Valuation-FCFF'!J18 -> -1889.4196
B19: FREE CASH FLOW TO FIRM (FCFF) | G19: =SUM(G11:G17) -> 6822.1904 | H19: =SUM(H11:H17) -> 7761.1938 | I19: =SUM(I11:I17) -> 8979.5536 | J19: =SUM(J11:J17) -> 10385.066
B22: Sensitivity Table
G23: (in ₹ Cr. unless stated otherwise)
B24: Revenue Growth | D24: 0.15 | G24: ='Valuation-FCFF'!L19 -> PV of FCFF (FY2027E-30E) | J24: =NPV(D27,G19:J19) -> 26455.812 | L24: Unit Share Price
B25: EBIT Margin | D25: 0.25 | G25: ='Valuation-FCFF'!L20 -> Terminal Value | J25: =J19*(1+D26)/(D27-D26)/(1+D27)^4 -> 252988.66
B26: Terminal Growth | D26: 0.07 | G26: ='Valuation-FCFF'!L21 -> Value of Firm | J26: =SUM(J24:J25) -> 279444.47 | L26: =J28/SOPL!O54*10000000 -> 2888.437
B27: ='Valuation-FCFF'!M16 -> WACC | D27: 0.1 | G27: ='Valuation-FCFF'!L22 -> Value of Debt | J27: ='Valuation-FCFF'!O22 -> 2554.11
B28: Tax Rate | D28: 0.15 | G28: ='Valuation-FCFF'!L23 -> Value of Equity | J28: =J26-J27 -> 276890.36
D30: Bear Case | K30: EBIT Margin
D31: Base Case | K31: 0.12 | L31: Upside/(Downside) | N31: =L26/D4-1 -> 0.090223078
D32: Bull Case | K32: 0.15
K33: 0.174
B34: The sensitivity analysis demonstrates the impact of changes in the Revenue Growth, EBIT Margin, Tax Rate, Weighted Average Cost of Capital (WACC) and Terminal Growth Rate on the estimated intrinsic value per share. The valuation remains highly sensitive to these assumptions because a significant proportion of enterprise value is derived from the terminal value calculation. A lower WACC or higher terminal growth rate results in a higher intrinsic value, whereas a higher discount rate or lower growth assumption reduces the estimated value.
B37: Terminal Growth | C37: WACC | D37: Revenue Growth | E37: Tax Rate | F37: ebit
B38: 0.02 | C38: 0.1 | D38: 0.06 | E38: 0.15 | F38: 0.12
B39: 0.03 | C39: 0.11 | D39: 0.07 | E39: 0.2 | F39: 0.15
B40: 0.0485 | C40: 0.1192 | D40: 0.0917 | E40: 0.268 | F40: 0.174
B41: 0.07 | C41: 0.13 | D41: 0.12 | E41: 0.3 | F41: 0.2
B42: 0.09 | C42: 0.15 | D42: 0.15 | E42: 0.35 | F42: 0.25

Sheet SOFP 
G2: NSE: ASIANPAINT | BSE:500820
G3: 52-WEEK (HIGH: ₹ 2985.70| LOW: ₹ 2115.00 )
G4: 2649.4
G5: (as at 13 July 2026)
B6: CONSOLIDATED STATEMENT OF FINANCIAL POSITION
B7: (in ₹ Cr. unless stated otherwise)
I8: Historical | P8: Forecasts
B9: Years | I9: =J9-1 -> 20 | J9: 21 | K9: =J9+1 -> 22 | L9: =K9+1 -> 23 | M9: =L9+1 -> 24 | N9: =M9+1 -> 25 | O9: =N9+1 -> 26 | P9: =O9+1 -> 27 | Q9: =P9+1 -> 28 | R9: =Q9+1 -> 29 | S9: =R9+1 -> 30 | T9: Trend
B11: ASSETS
B12: Non-Current Assets
B13: Property, Plant & Equipment | I13: 4764.76 | J13: 4476.35 | K13: 4184.46 | L13: 4145.65 | M13: 4446.2 | N13: 6787.62 | O13: 7146.23 | P13: =Schedule!AA18 -> 7322.745 | Q13: =Schedule!AD18 -> 7562.6993 | R13: =Schedule!AG18 -> 7867.2348 | S13: =Schedule!AJ18 -> 8238.0609
B14: Right-of-Use Assets | I14: 920.09 | J14: 845.55 | K14: 905.75 | L14: 1208.92 | M14: 1856.27 | N14: 1843.72 | O14: 2018.77 | P14: =Schedule!M47 -> 2162.4989 | Q14: =Schedule!N47 -> 2316.4607 | R14: =Schedule!O47 -> 2481.3841 | S14: =Schedule!P47 -> 2658.0493
B15: Capital work-in-progress | I15: 140.24 | J15: 182.98 | K15: 426.43 | L15: 1019.59 | M15: 2698.37 | N15: 1254.49 | O15: 1848.67 | P15: =P13*Q68 -> 1847.6522 | Q15: =Q13*R68 -> 1908.1968 | R15: =R13*S68 -> 1985.0362 | S15: =S13*T68 -> 2078.6019
B16: Goodwill and Intangible Assets | I16: =319.99+267.47 -> 587.46 | J16: =302.63+233.99 -> 536.62 | K16: =242.86+185.99 -> 428.85 | L16: =228.48+187.41 -> 415.89 | M16: =419.19+424.96 -> 844.15 | N16: =219.58+369.18 -> 588.76 | O16: =219.08+256.2 -> 475.28 | P16: =Schedule!AA37 -> 690.85502 | Q16: =Schedule!AD37 -> 765.04743 | R16: =Schedule!AG37 -> 848.49359 | S16: =Schedule!AJ37 -> 942.04096
B17: Investment in Associates | I17: 456.63 | J17: 483.9 | K17: 515.47 | L17: 781.73 | M17: 583.13 | N17: 608 | O17: 656.09 | P17: =O17*(1+Q69) -> 696.02769 | Q17: =P17*(1+R69) -> 738.39648 | R17: =Q17*(1+S69) -> 783.34435 | S17: =R17*(1+T69) -> 831.0283
B18: Financial Assets | I18: =1049.74+4.21+68.24+248.31 -> 1370.5 | J18: =985.78+2.89+594.06 -> 1582.73 | K18: =551.36+2.4+486.05 -> 1039.81 | L18: =782.98+2.17+363.18 -> 1148.33 | M18: =801.38+1.78+606.51 -> 1409.67 | N18: =871.79+8.71+0+877.84 -> 1758.34 | O18: =119.82+5.36+1.57+1537.79 -> 1664.54 | P18: =O18*(1+Q70) -> 1838.2601 | Q18: =P18*(1+R70) -> 2030.1105 | R18: =Q18*(1+S70) -> 2241.9834 | S18: =R18*(1+T70) -> 2475.9685
B19: Deferred Tax Assets (Net) | I19: 16.8 | J19: 14.28 | K19: 26.02 | L19: 18.67 | M19: 23.32 | N19: 16.12 | O19: 15.74 | P19: =O19*(1+Q71) -> 15.944781 | Q19: =P19*(1+R71) -> 16.152225 | R19: =Q19*(1+S71) -> 16.362369 | S19: =R19*(1+T71) -> 16.575247
B20: Income Tax Assets (Net) | I20: 253.09 | J20: 152.23 | K20: 172.46 | L20: 189.52 | M20: 198.11 | N20: 221.62 | O20: 248.62 | P20: =O20*(1+Q72) -> 273.21386 | Q20: =P20*(1+R72) -> 300.24058 | R20: =Q20*(1+S72) -> 329.94083 | S20: =R20*(1+T72) -> 362.57907
B21: Other Non-Current Assets | I21: 65.09 | J21: 68.38 | K21: 132.87 | L21: 334.54 | M21: 327.81 | N21: 301.02 | O21: 275.91 | P21: =O21*(1+Q73) -> 292.19925 | Q21: =P21*(1+R73) -> 309.45018 | R21: =Q21*(1+S73) -> 327.71958 | S21: =R21*(1+T73) -> 347.06757
B22: Total Non-Current Assets | I22: =SUM(I13:I21) -> 8574.66 | J22: =SUM(J13:J21) -> 8343.02 | K22: =SUM(K13:K21) -> 7832.12 | L22: =SUM(L13:L21) -> 9262.84 | M22: =SUM(M13:M21) -> 12387.03 | N22: =SUM(N13:N21) -> 13379.69 | O22: =SUM(O13:O21) -> 14349.85 | P22: =SUM(P13:P21) -> 15139.397 | ... S22: =SUM(S13:S21) -> 17949.972
B24: Current Assets
B25: Inventories | I25: 3389.81 | J25: 3798.6 | K25: 6152.98 | L25: 6210.64 | M25: 5923.41 | N25: 6719.27 | O25: 5743.69 | P25: =SOPL!P17*'Ratio Analysis'!$Q$48/'Ratio Analysis'!$G$52 -> 6729.5664 | Q25: =SOPL!Q17*'Ratio Analysis'!$Q$48/'Ratio Analysis'!$G$52 -> 7344.7418 | R25: =SOPL!R17*'Ratio Analysis'!$Q$48/'Ratio Analysis'!$G$52 -> 8016.4273 | S25: =SOPL!S17*'Ratio Analysis'!$Q$48/'Ratio Analysis'!$G$52 -> 8749.7952
B26: Financial Assets
B27: Trade Receivables | I27: 1795.22 | J27: 2602.17 | K27: 3871.44 | L27: 4636.94 | M27: 4889.05 | N27: 4313.65 | O27: 4461.8 | P27: =SOPL!P13*'Ratio Analysis'!$Q$49/'Ratio Analysis'!$G$52 -> 4940.7675 | Q27: =SOPL!Q13*'Ratio Analysis'!$Q$49/'Ratio Analysis'!$G$52 -> 5392.4219 | R27: =SOPL!R13*'Ratio Analysis'!$Q$49/'Ratio Analysis'!$G$52 -> 5885.5654 | S27: =SOPL!S13*'Ratio Analysis'!$Q$49/'Ratio Analysis'!$G$52 -> 6423.9953
B28: Cash & Cash Equivalents | I28: 563.83 | J28: 346.39 | K28: 621.72 | L28: 523.1 | M28: 829.34 | N28: 445.28 | O28: 672.83 | P28: =SOCF!Q64 -> 635.78825 | Q28: =SOCF!R64 -> 780.74675 | R28: =SOCF!S64 -> 894.29715 | S28: =SOCF!T64 -> 975.35534
B29: Other Balances with Bank | I29: 219 | J29: 264.36 | K29: 242.61 | L29: 320.72 | M29: 254.67 | N29: 336.7 | O29: 400.85 | P29: =SOCF!Q65 -> 378.78175 | Q29: =SOCF!R65 -> 465.14325 | R29: =SOCF!S65 -> 532.79285 | S29: =SOCF!T65 -> 581.08466
B30: Other Financial Assets | I30: =18.67+781.65+512.48 -> 1312.8 | J30: =1197.24+3267.12 -> 4464.36 | K30: =2180.7+1533.5 -> 3714.2 | L30: =2697+1592.78 -> 4289.78 | M30: =1651.35+3203.41 -> 4854.76 | N30: =1158.11+3244.96 -> 4403.07 | O30: =6285.83+0.46+1822.67 -> 8108.96 | P30: =O30*(1+Q74) -> 9162.0102 | Q30: =P30*(1+R74) -> 10351.812 | R30: =Q30*(1+S74) -> 11696.125 | S30: =R30*(1+T74) -> 13215.013
B31: Other Current Assets | I31: 285.59 | J31: 537.23 | K31: 541.25 | L31: 553.98 | M31: 785.83 | N31: 773.71 | O31: 796.51 | P31: =O31*(1+Q75) -> 814.14421 | Q31: =P31*(1+R75) -> 832.16883 | R31: =Q31*(1+S75) -> 850.5925 | S31: =R31*(1+T75) -> 869.42406
B32: Assets classified as Held for Sale | I32: 13.86 | J32: 13.49 | K32: 8.13 | L32: 0 | M32: 0 | N32: 0 | O32: 0 | P32: 0 | Q32: 0 | R32: 0 | S32: 0
B33: Total Current Assets | I33: =SUM(I25:I32) -> 7580.11 | J33: =SUM(J25:J32) -> 12026.6 | K33: =SUM(K25:K32) -> 15152.33 | L33: =SUM(L25:L32) -> 16535.16 | M33: =SUM(M25:M31) -> 17537.06 | N33: =SUM(N25:N31) -> 16991.68 | O33: =SUM(O25:O31) -> 20184.64 | P33: =SUM(P25:P31) -> 22661.058 | Q33: =SUM(Q25:Q31) -> 25167.035 | R33: =SUM(R25:R31) -> 27875.8 | S33: =SUM(S25:S31) -> 30814.668
B34: TOTAL ASSETS | I34: =SUM(I22+I33) -> 16154.77 | J34: =SUM(J22+J33) -> 20369.62 | K34: =SUM(K22+K33) -> 22984.45 | L34: =SUM(L22+L33) -> 25798 | M34: =SUM(M22+M33) -> 29924.09 | N34: =SUM(N22+N33) -> 30371.37 | O34: =SUM(O22+O33) -> 34534.49 | P34: =SUM(P22+P33) -> 37800.455 | ... S34: =SUM(S22+S33) -> 48764.64
B36: EQUITY AND LIABILITIES
B37: Equity
B38: Equity Share capital | I38: 95.92 | J38: 95.92 | K38: 95.92 | L38: 95.92 | M38: 95.92 | N38: 95.92 | O38: 95.92 | P38: 95.92 | Q38: 95.92 | R38: 95.92 | S38: 95.92
B39: Other Equity | I39: =10034.24 -> 10034.24 | J39: =12710.37 -> 12710.37 | K39: =13715.64 -> 13715.64 | L39: =15896.31 -> 15896.31 | M39: =18632.38 -> 18632.38 | N39: =19303.89 -> 19303.89 | O39: =21275.67 -> 21275.67 | P39: =O39+(SOPL!P32-SOPL!P33)*(1-Q76) -> 23067.189 | Q39: =P39+(SOPL!Q32-SOPL!Q33)*(1-R76) -> 25019.721 | R39: =Q39+(SOPL!R32-SOPL!R33)*(1-S76) -> 27144.847 | S39: =R39+(SOPL!S32-SOPL!S33)*(1-T76) -> 29455.111
B40: NCI | I40: 403.53 | J40: 422.86 | K40: 387.53 | L40: 453.66 | M40: 695.38 | N40: 659.24 | O40: 643.39 | P40: =O40+(SOPL!P32-SOPL!P33)*'SOFP '!Q76 -> 705.04298 | Q40: =P40+(SOPL!Q32-SOPL!Q33)*'SOFP '!R76 -> 772.23706 | R40: =Q40+(SOPL!R32-SOPL!R33)*'SOFP '!S76 -> 845.37071 | S40: =R40+(SOPL!S32-SOPL!S33)*'SOFP '!T76 -> 924.87569
B41: Total Equity | I41: =SUM(I38:I40) -> 10533.69 | J41: =SUM(J38:J40) -> 13229.15 | K41: =SUM(K38:K40) -> 14199.09 | L41: =SUM(L38:L40) -> 16445.89 | M41: =SUM(M38:M40) -> 19423.68 | N41: =SUM(N38:N40) -> 20059.05 | O41: =SUM(O38:O40) -> 22014.98 | P41: =SUM(P38:P40) -> 23868.152 | ... S41: =SUM(S38:S40) -> 30475.906
B43: Liabilities
B44: Non-Current Liabilities
B45: Financial Liabilities
...

Sheet SOPL
G2: NSE: ASIANPAINT | BSE:500820
G3: 52-WEEK (HIGH: ₹ 2985.70| LOW: ₹ 2115.00 )
G4: 2649.4
G5: (as at 13 July 2026)
B6: CONSOLIDATED STATEMENT OF PROFIT AND LOSS
B7: (in ₹ Cr. unless stated otherwise)
I8: Historical | P8: Forecasts
B9: Years | I9: =J9-1 -> 20 | J9: 21 | K9: =J9+1 -> 22 | L9: =K9+1 -> 23 | M9: =L9+1 -> 24 | N9: =M9+1 -> 25 | O9: =N9+1 -> 26 | P9: =O9+1 -> 27 | Q9: =P9+1 -> 28 | R9: =Q9+1 -> 29 | S9: =R9+1 -> 30
B11: Revenue from Sale of Products and Services | I11: =20025.96+22.36 -> 20048.32 | J11: =21440.24+44.96 -> 21485.2 | K11: =28830.02+93.46 -> 28923.48 | L11: =34253.35+114.48 -> 34367.83 | M11: =35248.88+133.24 -> 35382.12 | N11: =33626.82+170.54 -> 33797.36 | O11: =35416.25+100.12 -> 35516.37 | P11: =O11*(1+Q42) -> 38772.175 | Q11: =P11*(1+R42) -> 42326.44 | R11: =Q11*(1+S42) -> 46206.528 | S11: =R11*(1+T42) -> 50442.305
B12: Other Operating Revenue | I12: 162.93 | J12: 227.59 | K12: 177.8 | L12: 120.76 | M12: 112.61 | N12: 108.26 | O12: 67.17 | P12: =O12*(1+Q43) -> 62.636748 | Q12: =P12*(1+R43) -> 58.409442 | R12: =Q12*(1+S43) -> 54.467433 | S12: =R12*(1+T43) -> 50.791468
B13: REVENUE FROM OPERATIONS | I13: =SUM(I11:I12) -> 20211.25 | J13: =SUM(J11:J12) -> 21712.79 | K13: =SUM(K11:K12) -> 29101.28 | L13: =SUM(L11:L12) -> 34488.59 | M13: =SUM(M11:M12) -> 35494.73 | N13: =SUM(N11:N12) -> 33905.62 | O13: =SUM(O11:O12) -> 35583.54 | P13: =SUM(P11:P12) -> 38834.811 | ... S13: =SUM(S11:S12) -> 50493.096
B14: Materials Cost | I14: 10091.78 | J14: 10317.09 | K14: 16254.59 | L14: 17330.58 | M14: 15868.21 | N14: 15793.92 | O14: 15384.05 | P14: =P$13*Q44 -> 18452.822 | Q14: =Q$13*R44 -> 20139.665 | R14: =R$13*S44 -> 21981.461 | S14: =S$13*T44 -> 23992.394
B15: Purchases of Stock-in-Trade | I15: 1530.83 | J15: 1872.59 | K15: 3371.13 | L15: 4135.65 | M15: 3858.2 | N15: 3926.86 | O15: 4014.05 | P15: =P$13*Q45 -> 4380.8141 | Q15: =Q$13*R45 -> 4781.2811 | R15: =R$13*S45 -> 5218.535 | S15: =S$13*T45 -> 5695.9429
B16: Changes in Inventories | I16: -239.15 | J16: -92.45 | K16: -1324.97 | L16: -309.73 | M16: 363.8 | N16: -205 | O16: 603.68 | P16: =P$13*Q46 -> -234.80285 | Q16: =Q$13*R46 -> -256.26708 | R16: =R$13*S46 -> -279.70301 | S16: =S$13*T46 -> -305.29112
B17: COST OF GOODS SOLD | I17: =SUM(I14:I16) -> 11383.46 | J17: =SUM(J14:J16) -> 12097.23 | K17: =SUM(K14:K16) -> 18300.75 | L17: =SUM(L14:L16) -> 21156.5 | M17: =SUM(M14:M16) -> 20090.21 | N17: =SUM(N14:N16) -> 19515.78 | O17: =SUM(O14:O16) -> 20001.78 | P17: =SUM(P14:P16) -> 22598.833 | ... S17: =SUM(S14:S16) -> 29383.046
B18: GROSS MARGIN | I18: =I13-I17 -> 8827.79 | J18: =J13-J17 -> 9615.56 | K18: =K13-K17 -> 10800.53 | L18: =L13-L17 -> 13332.09 | M18: =M13-M17 -> 15404.52 | N18: =N13-N17 -> 14389.84 | O18: =O13-O17 -> 15581.76 | P18: =P13-P17 -> 16235.978 | ... S18: =S13-S17 -> 21110.05
B19: Other Non-Operating Income | I19: 304.31 | J19: 303.05 | K19: 380.01 | L19: 386.48 | M19: 687.96 | N19: 572.61 | O19: 723.8 | P19: =O19*(1+Q49) -> 836.24905 | Q19: =P19*(1+R49) -> 966.16811 | R19: =Q19*(1+S49) -> 1116.2713 | S19: =R19*(1+T49) -> 1289.6944
B20: Employee Benefits Expense | I20: 1366.09 | J20: 1540.75 | K20: 1786.67 | L20: 2028.07 | M20: 2326.18 | N20: 2597.23 | O20: 2799.59 | P20: =O20*(1+Q47) -> 3167.688 | Q20: =P20*(1+R47) -> 3584.1845 | R20: =Q20*(1+S47) -> 4055.4432 | S20: =R20*(1+T47) -> 4588.6643
B21: Other Expenses | I21: 3299.93 | J21: 3219.21 | K21: 4210.25 | L21: 5044.18 | M21: 5493.36 | N21: 5786.4 | O21: 6086.25 | P21: =P$13*Q48 -> 6010.2894 | Q21: =Q$13*R48 -> 6559.7129 | R21: =R$13*S48 -> 7159.6065 | S21: =S$13*T48 -> 7814.5898
B22: EBITDA | I22: =SUM(I18:I19)-SUM(I20:I21) -> 4466.08 | J22: =SUM(J18:J19)-SUM(J20:J21) -> 5158.65 | K22: =SUM(K18:K19)-SUM(K20:K21) -> 5183.62 | L22: =SUM(L18:L19)-SUM(L20:L21) -> 6646.32 | M22: =SUM(M18:M19)-SUM(M20:M21) -> 8272.94 | N22: =SUM(N18:N19)-SUM(N20:N21) -> 6578.82 | O22: =SUM(O18:O19)-SUM(O20:O21) -> 7419.72 | P22: =SUM(P18:P19)-SUM(P20:P21) -> 7894.25 | ... S22: =SUM(S18:S19)-SUM(S20:S21) -> 9996.4905
B23: Depreciation and Amortisation Expense | I23: 780.5 | J23: 791.27 | K23: 816.36 | L23: 858.02 | M23: 853 | N23: 1026.34 | O23: 1228.85 | P23: =Schedule!AG47 -> 1338.0711 | Q23: =Schedule!AH47 -> 1402.9337 | R23: =Schedule!AI47 -> 1477.7125 | S23: =Schedule!AJ47 -> 1562.8011
B24: EBIT | I24: =I22-I23 -> 3685.58 | J24: =J22-J23 -> 4367.38 | K24: =K22-K23 -> 4367.26 | L24: =L22-L23 -> 5788.3 | M24: =M22-M23 -> 7419.94 | N24: =N22-N23 -> 5552.48 | O24: =O22-O23 -> 6190.87 | P24: =P22-P23 -> 6556.1789 | ... S24: =S22-S23 -> 8433.6894
B25: Share of Profit in Associate | I25: 50.74 | J25: 28.6 | K25: 31.57 | L25: 93.85 | M25: 133 | N25: 140.71 | O25: 165.59 | P25: =O25*(1+Q50) -> 182.78588 | Q25: =P25*(1+R50) -> 201.7675 | R25: =Q25*(1+S50) -> 222.72027 | S25: =R25*(1+T50) -> 245.84892
B26: Exceptional Items | I26: 0 | J26: 0 | K26: -115.7 | L26: -48.87 | M26: 0 | N26: -363.1 | O26: -157.61 | P26: 0 | Q26: 0 | R26: 0 | S26: 0
B27: Finance Costs | I27: 102.33 | J27: 91.63 | K27: 95.41 | L27: 144.45 | M27: 205.17 | N27: 227.02 | O27: 195.41 | P27: =Schedule!M64 -> 209.84591 | Q27: =Schedule!N64 -> 225.34826 | R27: =Schedule!O64 -> 241.99586 | S27: =Schedule!P64 -> 259.87329
B28: PROFIT BEFORE TAX | I28: =SUM(I24:I26)-I27 -> 3633.99 | J28: =SUM(J24:J26)-J27 -> 4304.35 | K28: =SUM(K24:K26)-K27 -> 4187.72 | L28: =SUM(L24:L26)-L27 -> 5688.83 | M28: =SUM(M24:M26)-M27 -> 7347.77 | N28: =SUM(N24:N26)-N27 -> 5103.07 | O28: =SUM(O24:O26)-O27 -> 6003.44 | P28: =SUM(P24:P26)-P27 -> 6529.1188 | ... S28: =SUM(S24:S26)-S27 -> 8419.665
B29: Tax Expense | I29: 854.85 | J29: 1097.6 | K29: 1102.91 | L29: 1493.5 | M29: 1790.08 | N29: 1393.36 | O29: 1608.75 | P29: =P28*Q51 -> 1749.6169 | Q29: =Q28*R51 -> 1906.8648 | R29: =R28*S51 -> 2075.4209 | S29: =S28*T51 -> 2256.2291
B30: (Loss)/Profit from Discontinued Operations | I30: -4.95 | J30: 0 | K30: 0 | L30: 0 | M30: 0 | N30: 0 | O30: 0 | P30: 0 | Q30: 0 | R30: 0 | S30: 0
B31: PROFIT AFTER TAX | I31: =I28-I29+I30 -> 2774.19 | J31: =J28-J29+J30 -> 3206.75 | K31: =K28-K29+K30 -> 3084.81 | L31: =L28-L29+L30 -> 4195.33 | M31: =M28-M29+M30 -> 5557.69 | N31: =N28-N29+N30 -> 3709.71 | O31: =O28-O29+O30 -> 4394.69 | P31: =P28-P29+P30 -> 4779.502 | ... S31: =S28-S29+S30 -> 6163.4359
B32: Profit attributable to owners | I32: 2705.17 | J32: 3139.29 | K32: 3030.57 | L32: 4106.45 | M32: 5460.23 | N32: 3667.23 | O32: 4325.35 | P32: =P31*Q52 -> 4704.0903 | Q32: =Q31*R52 -> 5126.8733 | R32: =R31*S52 -> 5580.0603 | S32: =S31*T52 -> 6066.1884
B33: Dividend | I33: 1151.04 | J33: 1712.17 | K33: 1836.68 | L33: 2532.28 | M33: 3194.13 | N33: 2378.81 | O33: 2637.79 | P33: =P32*Q53 -> 2850.9187 | Q33: =Q32*R53 -> 3107.1467 | R33: =R32*S53 -> 3381.8012 | S33: =S32*T53 -> 3676.4196
B34: Earnings Per Share (EPS) (Basic) | H34: ₹/share | I34: 28.2 | J34: 32.73 | K34: 31.59 | L34: 42.83 | M34: 56.95 | N34: 38.25 | O34: 45.12 | P34: =P32/Q54*10000000 -> 49.071657 | Q34: =Q32/R54*10000000 -> 53.482002 | R34: =R32/S54*10000000 -> 58.209512 | S34: =S32/T54*10000000 -> 63.280655
B35: Dividend Per Share (DPS) | H35: ₹/share | I35: =I33/$I$54*10000000 -> 12.000028 | J35: =J33/$I$54*10000000 -> 17.85002 | K35: =K33/$I$54*10000000 -> 19.148084 | L35: =L33/$I$54*10000000 -> 26.399977 | M35: =M33/$I$54*10000000 -> 33.300014 | N35: =N33/$I$54*10000000 -> 24.799995 | O35: =O33/$I$54*10000000 -> 27.499959 | P35: =P33/P54*10000000 -> 29.739927 | Q35: =Q33/Q54*10000000 -> 32.412821 | R35: =R33/R54*10000000 -> 35.277934 | S35: =S33/S54*10000000 -> 38.351305
B36: NOTE: Reported EBIT includes Other Non-Operating Income and is taken as it is to reconcile with the publically issued historical ASIAN PAINTS LTD. INTEGRATED FINANCIAL REPORTS. For the purpose of FCFF Valuation, the Adjusted EBIT (Reported EBIT less Other Non-Operating Income) is used .
B38: FORECAST ASSUMPTIONS & BASIS
B40: Years | I40: =J40-1 -> 20 | J40: 21 | K40: =J40+1 -> 22 | L40: =K40+1 -> 23 | M40: =L40+1 -> 24 | N40: =M40+1 -> 25 | O40: =N40+1 -> 26 | P40: Basis | Q40: =O40+1 -> 27 | R40: =Q40+1 -> 28 | S40: =R40+1 -> 29 | T40: =S40+1 -> 30
B42: Revenue from Sale of Product and Services Growth % | I42: 0 | J42: =J11/I11-1 -> 0.071670843 | K42: =K11/J11-1 -> 0.34620483 | L42: =L11/K11-1 -> 0.18823288 | M42: =M11/L11-1 -> 0.029512774 | N42: =N11/M11-1 -> -0.044789854 | O42: =O11/N11-1 -> 0.050862257 | P42: =AVERAGE(I42:O42) -> 0.091670533 | Q42: =P42 -> 0.091670533 | R42: =Q42 -> 0.091670533 | S42: =R42 -> 0.091670533 | T42: =S42 -> 0.091670533
B43: Other Operating Revenue Growth % | I43: 0 | J43: =J12/I12-1 -> 0.39685755 | K43: =K12/J12-1 -> -0.2187706 | L43: =L12/K12-1 -> -0.3208099 | M43: =M12/L12-1 -> -0.067489235 | N43: =N12/M12-1 -> -0.038628896 | O43: =O12/N12-1 -> -0.37954923 | P43: =MEDIAN(I43:O43) -> -0.067489235 | Q43: =P43 -> -0.067489235 | R43: =Q43 -> -0.067489235 | S43: =R43 -> -0.067489235 | T43: =S43 -> -0.067489235
B44: Materials Cost as % of Revenue | I44: =I14/I$13 -> 0.49931499 | J44: =J14/J$13 -> 0.47516187 | K44: =K14/K$13 -> 0.55855241 | L44: =L14/L$13 -> 0.50250184 | M44: =M14/M$13 -> 0.4470582 | N44: =N14/N$13 -> 0.46582012 | O44: =O14/O$13 -> 0.43233613 | P44: =MEDIAN(I44:O44) -> 0.47516187 | Q44: =P44 -> 0.47516187 | R44: =Q44 -> 0.47516187 | S44: =R44 -> 0.47516187 | T44: =S44 -> 0.47516187
B45: Purchases of Stock-in-Trade as % of Revenue | I45: =I15/I$13 -> 0.075741481 | J45: =J15/J$13 -> 0.086243638 | K45: =K15/K$13 -> 0.1158413 | L45: =L15/L$13 -> 0.11991357 | M45: =M15/M$13 -> 0.10869783 | N45: =N15/N$13 -> 0.11581738 | O45: =O15/O$13 -> 0.11280637 | P45: =MEDIAN(I45:O45) -> 0.11280637 | Q45: =P45 -> 0.11280637 | R45: =Q45 -> 0.11280637 | S45: =R45 -> 0.11280637 | T45: =S45 -> 0.11280637
...

Sheet SOCF
D2: NSE: ASIANPAINT | BSE:500820
D3: 52-WEEK (HIGH: ₹ 2985.70| LOW: ₹ 2115.00 )
D4: 2649.4
D5: (as at 13 July 2026)
B6: CONSOLIDATED STATEMENT OF CASH FLOWS
B7: (in ₹ Cr. unless stated otherwise)
J8: Historical | Q8: Forecasts
B9: Years | J9: =K9-1 -> 20 | K9: 21 | L9: =K9+1 -> 22 | M9: =L9+1 -> 23 | N9: =M9+1 -> 24 | O9: =N9+1 -> 25 | P9: =O9+1 -> 26 | Q9: =P9+1 -> 27 | R9: =Q9+1 -> 28 | S9: =R9+1 -> 29 | T9: =S9+1 -> 30 | U9: Trend
B11: (A) CASH FLOW FROM OPERATING ACTIVITIES
B12: Profit before tax
B13: Continued Operations | J13: =SOPL!I28 -> 3633.99 | K13: =SOPL!J28 -> 4304.35 | L13: =SOPL!K28 -> 4187.72 | M13: =SOPL!L28 -> 5688.83 | N13: =SOPL!M28 -> 7347.77 | O13: =SOPL!N28 -> 5103.07 | P13: =SOPL!O28 -> 6003.44 | Q13: =SOPL!P28 -> 6529.1188 | ... T13: =SOPL!S28 -> 8419.665
B14: Discontinued Operations | J14: -5.73 | K14: 0 | L14: 0 | M14: 0 | N14: 0 | O14: 0 | P14: 0 | Q14: 0 | R14: 0 | S14: 0 | T14: 0
B15: Adjustments:
B16: Depreciation and Amortisation expense | J16: =SOPL!I23 -> 780.5 | K16: =SOPL!J23 -> 791.27 | L16: =SOPL!K23 -> 816.36 | M16: =SOPL!L23 -> 858.02 | N16: =SOPL!M23 -> 853 | O16: =SOPL!N23 -> 1026.34 | P16: =SOPL!O23 -> 1228.85 | Q16: =SOPL!P23 -> 1338.0711 | ... T16: =SOPL!S23 -> 1562.8011
B17: Finance Cost | J17: =SOPL!I27 -> 102.33 | K17: =SOPL!J27 -> 91.63 | L17: =SOPL!K27 -> 95.41 | M17: =SOPL!L27 -> 144.45 | N17: =SOPL!M27 -> 205.17 | O17: =SOPL!N27 -> 227.02 | P17: =SOPL!O27 -> 195.41 | Q17: =SOPL!P27 -> 209.84591 | ... T17: =SOPL!S27 -> 259.87329
B18: Share of Profit in Associates | J18: =-SOPL!I25 -> -50.74 | K18: =-SOPL!J25 -> -28.6 | L18: =-SOPL!K25 -> -31.57 | M18: =-SOPL!L25 -> -93.85 | N18: =-SOPL!M25 -> -133 | O18: =-SOPL!N25 -> -140.71 | P18: =-SOPL!O25 -> -165.59 | Q18: =-SOPL!P25 -> -182.78588 | ... T18: =-SOPL!S25 -> -245.84892
B19: Impairment loss on Goodwill and Intangible assets | J19: 0 | K19: 0 | L19: 13.47 | M19: -27.58 | N19: 0 | O19: 223.25 | P19: 93.87 | Q19: =Schedule!Z36 -> 25.72 | R19: =Q19 -> 25.72 | S19: =R19 -> 25.72 | T19: =S19 -> 25.72
B20: Other* | J20: =J21-SUM(J13:J19) -> -80.61 | K20: =K21-SUM(K13:K19) -> -189.12 | L20: =L21-SUM(L13:L19) -> -123.99 | M20: =M21-SUM(M13:M19) -> -110.05 | N20: =N21-SUM(N13:N19) -> -344.34 | O20: =-179.84-20.64+227.02+245.18-227.02+6.06-4.69-11.06-3.37-2.07-182.43+21.25+83.71-18.29-1.78+18.66 -> -49.31 | P20: =-180.93-2.13+5.7+121.95-4.08+2.94+3.81-6.87-286.5+29.35+19.96+70.17+56.93 -> -169.7 | Q20: =P20*(1+R73) -> -281.28826 | R20: =Q20*(1+S73) -> -466.2527 | S20: =R20*(1+T73) -> -772.84273 | T20: =S20*(1+U73) -> -1281.0347
B21: Operating Profit before working capital changes | J21: 4379.74 | K21: 4969.53 | L21: 4957.4 | M21: 6459.82 | N21: 7928.6 | O21: =SUM(O13:O20) -> 6389.66 | P21: =SUM(P13:P20) -> 7186.28 | Q21: =SUM(Q13:Q20) -> 7638.6817 | R21: =SUM(R12:R20) -> 8101.9091 | S21: =SUM(S12:S20) -> 8494.8009 | T21: =SUM(T12:T20) -> 8741.1758
B22: Change in Working Capital | J22: =J23-J21 -> -330.84 | K22: =K23-K21 -> -206.46 | L22: =L23-L21 -> -2795.22 | M22: =M23-M21 -> -772.11 | N22: =N23-N21 -> 10.05 | O22: =O23-O21 -> -570.18 | P22: =P23-P21 -> 1475.72 | Q22: =$Q$75*SOPL!P13 -> -635.69096 | R22: =$Q$75*SOPL!Q13 -> -693.8019 | S22: =$Q$75*SOPL!R13 -> -757.25092 | T22: =$Q$75*SOPL!S13 -> -826.52661
B23: Cash generated from Operating activities | J23: 4048.9 | K23: 4763.07 | L23: 2162.18 | M23: 5687.71 | N23: 7938.65 | O23: 5819.48 | P23: 8662 | Q23: =SUM(Q21:Q22) -> 7002.9908 | R23: =SUM(R21:R22) -> 7408.1072 | S23: =SUM(S21:S22) -> 7737.55 | T23: =SUM(T21:T22) -> 7914.6492
B24: Income Tax paid (net of refund) | J24: -1010.75 | K24: -1079.72 | L24: -1175.69 | M24: -1494.28 | N24: -1835.05 | O24: -1395.52 | P24: -1573.82 | Q24: =-R76*SOPL!P29 -> -1746.9088 | R24: =-S76*SOPL!Q29 -> -1903.9133 | S24: =-T76*SOPL!R29 -> -2072.2086 | T24: =-U76*SOPL!S29 -> -2252.7369
B25: Net Cash generated from Operating activities | J25: 3038.15 | K25: 3683.35 | L25: 986.49 | M25: 4193.43 | N25: 6103.6 | O25: =SUM(O23:O24) -> 4423.96 | P25: =SUM(P23:P24) -> 7088.18 | Q25: =SUM(Q23:Q24) -> 5256.082 | R25: =SUM(R23:R24) -> 5504.1939 | S25: =SUM(S23:S24) -> 5665.3414 | T25: =SUM(T23:T24) -> 5661.9123
B27: (B) CASH FLOW FROM INVESTING ACTIVITIES
B28: Net CapEx (PPE, Goodwill & Intangible Assets) | J28: =-403.54+36.6 -> -366.94 | K28: =-281.87+27.61 -> -254.26 | L28: =-538.24+39.58 -> -498.66 | M28: =-1273.37+25.92 -> -1247.45 | N28: =-2199.01+5.13 -> -2193.88 | O28: =-1805.32+10.1 -> -1795.22 | P28: =-1467.02+3.2 -> -1463.82 | Q28: =-Schedule!Z11-Schedule!Z26 -> -1109.7583 | R28: =-Schedule!AC11-Schedule!AC26 -> -1211.2055 | S28: =-Schedule!AF11-Schedule!AF26 -> -1321.9717 | T28: =-Schedule!AI11-Schedule!AI26 -> -1442.9098
B29: Payment for acquiring right-of-use assets | J29: -10.15 | K29: -6.84 | L29: -12.46 | M29: -172.24 | N29: -297.07 | O29: -24.75 | P29: -20.3 | Q29: =P29*(1+R74) -> -22.78598 | R29: =Q29*(1+S74) -> -25.576397 | S29: =R29*(1+T74) -> -28.708535 | T29: =S29*(1+U74) -> -32.224241
B30: Net Proceeds from sale of Financial Assets | J30: =J34-SUM(J28:J29,J32) -> -236.78 | K30: =-0.5+272.32-139.34-500.33 -> -367.85 | L30: =146.46+61.03-110.21 -> 97.28 | M30: =-146.07+376.61+69.43-118.71 -> 181.26 | N30: =-212.24+0.5+239.99-206.25-75-37.71 -> -290.71 | O30: =-0.92+420.65+196.8+38.29 -> 654.82 | P30: =-0.1+923.36+274.03-1316.03 -> -118.74 | Q30: =MEDIAN(J30:P30) -> -118.74 | R30: =Q30 -> -118.74 | S30: =R30 -> -118.74 | T30: =S30 -> -118.74
B31: Loan given to third party | J31: 0 | K31: 0 | L31: 0 | M31: 0 | N31: 0 | O31: 0 | P31: -2.03 | Q31: 0 | R31: 0 | S31: 0 | T31: 0
B32: Interest and Dividends Received | J32: =65.32+27.13 -> 92.45 | K32: =73.35+7.81 -> 81.16 | L32: =76.99+15.16 -> 92.15 | M32: =87.15+42.78+13.48 -> 143.41 | N32: =135.49+108.37+20.17 -> 264.03 | O32: =154.89+115.5+20.64 -> 291.03 | P32: =153.19+115.5+2.13 -> 270.82 | Q32: =R77*SOPL!P19 -> 310.30448 | R32: =S77*SOPL!Q19 -> 358.51317 | S32: =T77*SOPL!R19 -> 414.21151 | T32: =U77*SOPL!S19 -> 478.56312
B33: Other | J33: 0 | K33: 0 | L33: 0 | M33: =M34-SUM(M28:M32) -> -179.62 | N33: 0 | O33: 0 | P33: 0 | Q33: 0 | R33: 0 | S33: 0 | T33: 0
B34: Net Cash used in Investing activities | J34: -521.42 | K34: =SUM(K28:K33) -> -547.79 | L34: =SUM(L28:L33) -> -321.69 | M34: -1274.64 | N34: =SUM(N28:N33) -> -2517.63 | O34: =SUM(O28:O33) -> -874.12 | P34: =SUM(P28:P33) -> -1334.07 | Q34: =SUM(Q28:Q33) -> -940.97977 | R34: =SUM(R28:R33) -> -997.00876 | S34: =SUM(S28:S33) -> -1055.2087 | T34: =SUM(T28:T33) -> -1115.311
B36: (C) CASH FLOW FROM FINANCING ACTIVITIES
B37: Net Proceeds from Long-term Borrowings | J37: =17.91-10.49 -> 7.42 | K37: =2.14-14.21 -> -12.07 | L37: =39.87-7.89 -> 31.98 | M37: =94-15.55 -> 78.45 | N37: =5.91-14.17 -> -8.26 | O37: =219.84-21.16 -> 198.68 | P37: =993.41-32.43 -> 960.98 | Q37: =AVERAGE(J37:P37) -> 179.59714 | R37: =AVERAGE(K37:Q37) -> 204.19388 | S37: =AVERAGE(L37:R37) -> 235.08872 | T37: =AVERAGE(M37:S37) -> 264.10425
B38: Proceeds from / (Repayment of) short term borrowings (net) | J38: -268.79 | K38: 37.78 | L38: 292.68 | M38: 159.76 | N38: 94.98 | O38: -406.41 | P38: 285.44 | Q38: =MEDIAN(J38:P38) -> 94.98 | R38: =MEDIAN(K38:Q38) -> 94.98 | S38: =MEDIAN(L38:R38) -> 94.98 | T38: =MEDIAN(M38:S38) -> 94.98
B39: Finance costs (including interest on lease liabilities) paid | J39: -100.89 | K39: -89.31 | L39: -93.56 | M39: -141.95 | N39: -190.57 | O39: -203.19 | P39: -228.33 | Q39: =-SUM(Schedule!M58:M61) -> -202.25057 | R39: =-SUM(Schedule!N58:N61) -> -217.19183 | S39: =-SUM(Schedule!O58:O61) -> -233.23686 | T39: =-SUM(Schedule!P58:P61) -> -250.46723
B40: Dividend paid (including dividend paid to non-controlling shareholders) | J40: -2120.71 | K40: -499.35 | L40: -1762.8 | M40: -1936.05 | N40: -2550.88 | O40: -3140.21 | P40: -2425.38 | Q40: =MEDIAN(J40:P40) -> -2120.71 | R40: =MEDIAN(K40:Q40) -> -2120.71 | S40: =MEDIAN(L40:R40) -> -2120.71 | T40: =MEDIAN(M40:S40) -> -2120.71
B41: Other | J41: =J42-SUM(J37:J40) -> -388.49 | K41: =K42-SUM(K37:K40) -> -87.45 | L41: =L42-SUM(L37:L40) -> -275.91 | M41: =M42-SUM(M37:M40) -> -300.26 | N41: =N42-SUM(N37:N40) -> -327.77 | O41: =O42-SUM(O37:O40) -> -201.45 | P41: =P42-SUM(P37:P40) -> -969.22 | Q41: =P41*(1+((P41/J41)^(1/6)-1)) -> -1128.7457 | R41: =Q41*(1+((Q41/K41)^(1/6)-1)) -> -1728.7632 | S41: =R41*(1+((R41/L41)^(1/6)-1)) -> -2347.2725 | T41: =S41*(1+((S41/M41)^(1/6)-1)) -> -3306.7994
B42: Net Cash used in Financing activities | J42: -2871.46 | K42: -650.4 | L42: -1807.61 | M42: -2140.05 | N42: -2982.5 | O42: -3752.58 | P42: =-2376.51 -> -2376.51 | Q42: =SUM(Q37:Q41) -> -3177.1292 | R42: =SUM(R37:R41) -> -3767.4911 | S42: =SUM(S37:S41) -> -4371.1507 | T42: =SUM(T37:T41) -> -5318.8924
B43: (D) NET INCREASE / (DECREASE) IN CASH AND CASH EQUIVALENTS [A+B+C] | J43: =J25+J34+J42 -> -354.73 | K43: =K25+K34+K42 -> 2485.16 | L43: =L25+L34+L42 -> -1142.81 | M43: =M25+M34+M42 -> 778.74 | N43: =N25+N34+N42 -> 603.47 | O43: =O25+O34+O42 -> -202.74 | P43: =P25+P34+P42 -> 3377.6 | Q43: =Q25+Q34+Q42 -> 1137.973 | ... T43: =T25+T34+T42 -> -772.29109
B44: Add : Cash and cash equivalents as at 1st April | J44: 1279.97 | K44: 928.75 | L44: 3421.16 | M44: 2283.29 | N44: 3054.33 | O44: 3626.95 | P44: 3357.42 | Q44: =P46 -> 6740.86 | R44: =Q46 -> 7878.833 | S44: =R46 -> 8618.5271 | T44: =S46 -> 8857.509
...

Sheet Schedule
C2: NSE: ASIANPAINT | BSE:500820
C3: 52-WEEK (HIGH: ₹ 2985.70| LOW: ₹ 2115.00 ) | R3: SUPPORTING SCHEDULES | AJ3: -Basis for Forecasting
C4: 2649.4 | AI4: (B) | AJ4: -Balancing Adjustment
C5: (as at 13 July 2026)
B6: PROPERTY, PLANT & EQUIPMENT
B7: (in ₹ Cr. unless stated otherwise)
C8: Gross Carrying Value | Y8: Gross Carrying Value
B9: Years | C9: =20 -> 20 | F9: =C9+1 -> 21 | I9: =F9+1 -> 22 | L9: =I9+1 -> 23 | O9: =L9+1 -> 24 | R9: =O9+1 -> 25 | U9: =R9+1 -> 26 | X9: Basis | Y9: 27 | AB9: =Y9+1 -> 28 | AE9: =AB9+1 -> 29 | AH9: =AE9+1 -> 30
C10: Opening Balance | D10: Addition/ Adjustments | E10: Gross | F10: =C10 -> Opening Balance | G10: =D10 -> Addition/ Adjustments | H10: =E10 -> Gross | I10: =F10 -> Opening Balance | J10: =G10 -> Addition/ Adjustments | K10: =H10 -> Gross | L10: =I10 -> Opening Balance | M10: =J10 -> Addition/ Adjustments | ... W10: =T10 -> Gross | Y10: Opening Balance | Z10: Addition/ Adjustments | AA10: Gross | AB10: =Y10 -> Opening Balance | AC10: =Z10 -> Addition/ Adjustments | AD10: =AA10 -> Gross | AE10: =AB10 -> Opening Balance | AF10: =AC10 -> Addition/ Adjustments | AG10: =AD10 -> Gross | AH10: =AE10 -> Opening Balance | AI10: =AF10 -> Addition/ Adjustments | AJ10: =AG10 -> Gross
C11: 6302.92 | D11: =30.72+294.98-32.91-28.02 -> 264.77 | E11: =C11+D11 -> 6567.69 | F11: =E11 -> 6567.69 | G11: =263.73-38.22-20.85 -> 204.66 | H11: =F11+G11 -> 6772.35 | I11: =H11 -> 6772.35 | J11: =269.34-22.76-22.07 -> 224.51 | K11: =I11+J11 -> 6996.86 | L11: =K11 -> 6996.86 | M11: =0.92+533.78-20.41-29.37 -> 484.92 | N11: =L11+M11 -> 7481.78 | O11: =N11 -> 7481.78 | P11: =18.69-13.6-21.62+786.65 -> 770.12 | Q11: =O11+P11 -> 8251.9 | R11: =Q11 -> 8251.9 | S11: =3100.17-160.64-59.74-28.71 -> 2851.08 | T11: =R11+S11 -> 11102.98 | U11: =T11 -> 11102.98 | V11: =85.06+1111.01-166.5 -> 1029.57 | W11: =U11+V11 -> 12132.55 | Y11: =W11 -> 12132.55 | Z11: =$X$12*SOPL!P13 -> 983.11539 | AA11: =Y11+Z11 -> 13115.665 | AB11: =AA11 -> 13115.665 | AC11: =X12*SOPL!Q13 -> 1072.9857 | AD11: =AB11+AC11 -> 14188.651 | AE11: =AD11 -> 14188.651 | AF11: =X12*SOPL!R13 -> 1171.1116 | AG11: =AE11+AF11 -> 15359.763 | AH11: =AG11 -> 15359.763 | AI11: =X12*SOPL!S13 -> 1278.2485 | AJ11: =AH11+AI11 -> 16638.011
B12: CapEx as % of Revenue | D12: =D11/SOPL!I$13 -> 0.01310013 | G12: =G11/SOPL!J$13 -> 0.0094257808 | J12: =J11/SOPL!K$13 -> 0.0077147809 | M12: =M11/SOPL!L$13 -> 0.014060302 | P12: =P11/SOPL!M$13 -> 0.021696742 | S12: =S11/SOPL!N$13 -> 0.084088714 | V12: =V11/SOPL!O$13 -> 0.028933883 | X12: =MEDIAN(M12,P12,S12,V12) -> 0.025315313 | Z12: =Z27 -> (CAPEX) | AC12: =AC27 -> (CAPEX) | AF12: =AF27 -> (CAPEX) | AI12: =AI27 -> (CAPEX)
C13: Depreciation | Y13: Depreciation
B14: Years | C14: =20 -> 20 | F14: =C14+1 -> 21 | I14: =F14+1 -> 22 | L14: =I14+1 -> 23 | O14: =L14+1 -> 24 | R14: =O14+1 -> 25 | U14: =R14+1 -> 26 | Y14: =Y9 -> 27 | AB14: =Y14+1 -> 28 | AE14: =AB14+1 -> 29 | AH14: =AE14+1 -> 30
C15: Opening Balance | D15: =D10 -> Addition/ Adjustments | E15: Gross | F15: =C15 -> Opening Balance | G15: =D15 -> Addition/ Adjustments | H15: =E15 -> Gross | I15: =F15 -> Opening Balance | J15: =G15 -> Addition/ Adjustments | K15: =H15 -> Gross | L15: =I15 -> Opening Balance | M15: =J15 -> Addition/ Adjustments | ... W15: =T15 -> Gross | Y15: =Y10 -> Opening Balance | Z15: =Z10 -> Addition/ Adjustments | AA15: =AA10 -> Gross | AB15: =AB10 -> Opening Balance | AC15: =AC10 -> Addition/ Adjustments | AD15: =AD10 -> Gross | AE15: =AE10 -> Opening Balance | AF15: =AF10 -> Addition/ Adjustments | ... AJ15: =AJ10 -> Gross
C16: 1272.48 | D16: =14.07+533.39-7.66-9.35 -> 530.45 | E16: =C16+D16 -> 1802.93 | F16: =E16 -> 1802.93 | G16: =544.45-34.8-16.58 -> 493.07 | H16: =F16+G16 -> 2296 | I16: =H16 -> 2296 | J16: =546.29-12.67-17.22 -> 516.4 | K16: =I16+J16 -> 2812.4 | L16: =K16 -> 2812.4 | M16: =551.5-4.08-23.69 -> 523.73 | N16: =L16+M16 -> 3336.13 | O16: =N16 -> 3336.13 | P16: =8.09+483.64-18.57-3.59 -> 469.57 | Q16: =O16+P16 -> 3805.7 | R16: =Q16 -> 3805.7 | S16: =617.08-11-53-43.42 -> 509.66 | T16: =R16+S16 -> 4315.36 | U16: =T16 -> 4315.36 | V16: =21.13+809.32-159.49 -> 670.96 | W16: =U16+V16 -> 4986.32 | Y16: =W16 -> 4986.32 | Z16: =$X$17*(Y11+Z11-Y16) -> 806.60043 | AA16: =Y16+Z16 -> 5792.9204 | AB16: =AA16 -> 5792.9204 | AC16: =X17*(AB11+AC11-AB16) -> 833.03141 | AD16: =AB16+AC16 -> 6625.9518 | AE16: =AD16 -> 6625.9518 | AF16: =X17*(AE11+AF11-AE16) -> 866.576 | AG16: =AE16+AF16 -> 7492.5278 | AH16: =AG16 -> 7492.5278 | AI16: =X17*(AH11+AI11-AH16) -> 907.42249 | AJ16: =AH16+AI16 -> 8399.9503
B17: Depreciation % | E17: =D16/(C11+D11-C16) -> 0.10017544 | H17: =G16/(F11+G11-F16) -> 0.099220835 | K17: =J16/(I11+J11-I16) -> 0.10985224 | N17: =M16/(L11+M11-L16) -> 0.11216264 | Q17: =P16/(O11+P11-O16) -> 0.095523184 | T17: =S16/(R11+S11-R16) -> 0.069842462 | W17: =V16/(U11+V11-U16) -> 0.085831354 | X17: =MEDIAN(N17,E17,H17,K17,Q17,T17,W17) -> 0.099220835 | Z17: (Depreciation) | AC17: =Z17 -> (Depreciation) | AF17: =AC17 -> (Depreciation) | AI17: =AF17 -> (Depreciation)
B18: Year-end Carrying Value | E18: =E11-E16 -> 4764.76 | H18: =H11-H16 -> 4476.35 | K18: =K11-K16 -> 4184.46 | N18: =N11-N16 -> 4145.65 | Q18: =Q11-Q16 -> 4446.2 | T18: =T11-T16 -> 6787.62 | W18: =W11-W16 -> 7146.23 | AA18: =AA11-AA16 -> 7322.745 | AD18: =AD11-AD16 -> 7562.6993 | AG18: =AG11-AG16 -> 7867.2348 | AJ18: =AJ11-AJ16 -> 8238.0609
B21: GOODWILL & INTANGIBLE ASSETS
B22: (in ₹ Cr. unless stated otherwise)
C23: Gross Carrying Value | Y23: Gross Carrying Value
B24: Years | C24: =20 -> 20 | F24: =C24+1 -> 21 | I24: =F24+1 -> 22 | L24: =I24+1 -> 23 | O24: =L24+1 -> 24 | R24: =O24+1 -> 25 | U24: =R24+1 -> 26 | X24: Basis | Y24: 27 | AB24: =Y24+1 -> 28 | AE24: =AB24+1 -> 29 | AH24: =AE24+1 -> 30
C25: Opening Balance | D25: Addition/ Adjustments | E25: Gross | F25: =C25 -> Opening Balance | G25: =D25 -> Addition/ Adjustments | H25: =E25 -> Gross | I25: =F25 -> Opening Balance | J25: =G25 -> Addition/ Adjustments | K25: =H25 -> Gross | L25: =I25 -> Opening Balance | M25: =J25 -> Addition/ Adjustments | ... W25: =T25 -> Gross | Y25: Opening Balance | Z25: Addition/ Adjustments | AA25: Gross | AB25: =Y25 -> Opening Balance | AC25: =Z25 -> Addition/ Adjustments | AD25: =AA25 -> Gross | AE25: =AB25 -> Opening Balance | AF25: =AC25 -> Addition/ Adjustments | AG25: =AD25 -> Gross | AH25: =AE25 -> Opening Balance | AI25: =AF25 -> Addition/ Adjustments | AJ25: =AG25 -> Gross
C26: 769.15 | D26: =31.72-2.77-3.69-0.15 -> 25.11 | E26: =C26+D26 -> 794.26 | F26: =E26 -> 794.26 | G26: =15.82-36.13-0.2 -> -20.51 | H26: =F26+G26 -> 773.75 | I26: =H26 -> 773.75 | J26: =24.82-96.76-0.2 -> -72.14 | K26: =I26+J26 -> 701.61 | L26: =K26 -> 701.61 | M26: =12.98+30.48-35.52-1.76 -> 6.18 | N26: =L26+M26 -> 707.79 | O26: =N26 -> 707.79 | P26: =17.87+403.95+37.63 -> 459.45 | Q26: =O26+P26 -> 1167.24 | R26: =Q26 -> 1167.24 | S26: =25.16-25.9-13.57-0.94 -> -15.25 | T26: =R26+S26 -> 1151.99 | U26: =T26 -> 1151.99 | V26: =8.78+5.86-1.45 -> 13.19 | W26: =U26+V26 -> 1165.18 | Y26: =W26 -> 1165.18 | Z26: =X27*SOPL!P13 -> 126.64288 | AA26: =Y26+Z26 -> 1291.8229 | AB26: =AA26 -> 1291.8229 | AC26: =SOPL!Q13*X27 -> 138.21979 | AD26: =AB26+AC26 -> 1430.0427 | AE26: =AD26 -> 1430.0427 | AF26: =SOPL!R13*X27 -> 150.86016 | AG26: =AE26+AF26 -> 1580.9028 | AH26: =AG26 -> 1580.9028 | AI26: =SOPL!S13*X27 -> 164.66132 | AJ26: =AH26+AI26 -> 1745.5641
B27: CapEx as % of Revenue | D27: =D26/SOPL!I$13 -> 0.0012423774 | G27: =G26/SOPL!J$13 -> -0.00094460454 | J27: =J26/SOPL!K$13 -> -0.0024789288 | M27: =M26/SOPL!L$13 -> 0.0001791897 | P27: =P26/SOPL!M$13 -> 0.012944175 | S27: =S26/SOPL!N$13 -> -0.00044977794 | V27: =V26/SOPL!O$13 -> 0.000370677 | X27: =AVERAGE(M27,P27,S27,V27) -> 0.003261066 | Z27: (CAPEX) | AC27: (CAPEX) | AF27: (CAPEX) | AI27: (CAPEX)
C28: Amortisation | Y28: Amortisation
B29: Years | C29: =20 -> 20 | F29: =C29+1 -> 21 | I29: =F29+1 -> 22 | L29: =I29+1 -> 23 | O29: =L29+1 -> 24 | R29: =O29+1 -> 25 | U29: =R29+1 -> 26 | Y29: =Y24 -> 27 | AB29: =Y29+1 -> 28 | AE29: =AB29+1 -> 29 | AH29: =AE29+1 -> 30
C30: Opening Balance | D30: =D25 -> Addition/ Adjustments | E30: Gross | F30: =C30 -> Opening Balance | G30: =D30 -> Addition/ Adjustments | H30: =E30 -> Gross | I30: =F30 -> Opening Balance | J30: =G30 -> Addition/ Adjustments | K30: =H30 -> Gross | L30: =I30 -> Opening Balance | M30: =J30 -> Addition/ Adjustments | ... W30: =T30 -> Gross | Y30: Opening Balance | Z30: =Z25 -> Addition/ Adjustments | AA30: Gross | AB30: =Y30 -> Opening Balance | AC30: =Z30 -> Addition/ Adjustments | AD30: =AA30 -> Gross | AE30: =AB30 -> Opening Balance | AF30: =AC30 -> Addition/ Adjustments | AG30: =AD30 -> Gross | AH30: =AE30 -> Opening Balance | AI30: =AF30 -> Addition/ Adjustments | AJ30: =AG30 -> Gross
C31: 121.7 | D31: =0.27+35.15-2.77 -> 32.65 | E31: =C31+D31 -> 154.35 | F31: =E31 -> 154.35 | G31: =31.66-0.19-1.14 -> 30.33 | H31: =F31+G31 -> 184.68 | I31: =H31 -> 184.68 | J31: =28.83-6.63-0.19 -> 22.01 | K31: =I31+J31 -> 206.69 | L31: =K31 -> 206.69 | M31: =29.09-35.13-0.54 -> -6.58 | N31: =L31+M31 -> 200.11 | O31: =N31 -> 200.11 | P31: =27.34+1.76 -> 29.1 | Q31: =O31+P31 -> 229.21 | R31: =Q31 -> 229.21 | S31: =31.09-13.57-0.8-1.38 -> 15.34 | T31: =R31+S31 -> 244.55 | U31: =T31 -> 244.55 | V31: =1.41+27.04-1.45 -> 27 | W31: =U31+V31 -> 271.55 | Y31: 121.7 | Z31: =X32*(Y26+Z26-Y31) -> 35.207858 | AA31: =Y31+Z31 -> 156.90786 | AB31: =AA31 -> 156.90786 | AC31: =X32*(AB26+AC26-AB31) -> 38.307387 | AD31: =AB31+AC31 -> 195.21525 | AE31: =AD31 -> 195.21525 | AF31: =X32*(AE26+AF26-AE31) -> 41.69399 | AG31: =AE31+AF31 -> 236.90924 | AH31: =AG31 -> 236.90924 | AI31: =X32*(AH26+AI26-AH31) -> 45.393957 | AJ31: =AH31+AI31 -> 282.30319
B32: Amortisation % | E32: =D31/(C26+D26-C31) -> 0.048545855 | H32: =G31/(F26+G26-F31) -> 0.048966742 | K32: =J31/(I26+J26-I31) -> 0.042578299 | N32: =M31/(L26+M26-L31) -> -0.013131112 | Q32: =P31/(O26+P26-O31) -> 0.030089026 | T32: =S31/(R26+S26-R31) -> 0.016623681 | W32: =V31/(U26+V26-U31) -> 0.029327743 | X32: =MEDIAN(N32,E32,H32,K32,Q32,T32,W32) -> 0.030089026 | Z32: (Amortisation) | AC32: (Amortisation) | AF32: (Amortisation) | AI32: (Amortisation)
C33: Impairment | Y33: Impairment
B34: Years | C34: =20 -> 20 | F34: =C34+1 -> 21 | I34: =F34+1 -> 22 | L34: =I34+1 -> 23 | O34: =L34+1 -> 24 | R34: =O34+1 -> 25 | U34: =R34+1 -> 26 | Y34: 27 | AB34: =Y34+1 -> 28 | AE34: =AB34+1 -> 29 | AH34: =AE34+1 -> 30
C35: Opening Balance | D35: =D30 -> Addition/ Adjustments | E35: Gross | F35: =C35 -> Opening Balance | G35: =D35 -> Addition/ Adjustments | H35: =E35 -> Gross | I35: =F35 -> Opening Balance | J35: =G35 -> Addition/ Adjustments | K35: =H35 -> Gross | L35: =I35 -> Opening Balance | M35: =J35 -> Addition/ Adjustments | ... W35: =T35 -> Gross | Y35: Opening Balance | Z35: =Z30 -> Addition/ Adjustments | AA35: Gross | AB35: =Y35 -> Opening Balance | AC35: =Z35 -> Addition/ Adjustments | AD35: =AA35 -> Gross | AE35: =AB35 -> Opening Balance | AF35: =AC35 -> Addition/ Adjustments | AG35: =AD35 -> Gross | AH35: =AE35 -> Opening Balance | AI35: =AF35 -> Addition/ Adjustments | AJ35: =AG35 -> Gross
C36: 52.45 | D36: 0 | E36: =C36+D36 -> 52.45 | F36: =E36 -> 52.45 | G36: 0 | H36: =F36 -> 52.45 | I36: =H36 -> 52.45 | J36: =0.15+13.47 -> 13.62 | K36: =I36+J36 -> 66.07 | L36: =K36 -> 66.07 | M36: =1.06+24.66 -> 25.72 | N36: =L36+M36 -> 91.79 | O36: =N36 -> 91.79 | P36: =1.4+0.68 -> 2.08 | Q36: =O36+P36 -> 93.87 | R36: =Q36 -> 93.87 | S36: =1.55+223.25 -> 224.8 | T36: =R36+S36 -> 318.67 | U36: =T36 -> 318.67 | V36: =5.8+93.87 -> 99.67 | W36: =U36+V36 -> 418.34 | X36: =MEDIAN(J36,M36,P36,S36,V36) -> 25.72 | Y36: =W36 -> 418.34 | Z36: =X36 -> 25.72 | AA36: =Y36+Z36 -> 444.06 | AB36: =AA36 -> 444.06 | AC36: =Z36 -> 25.72 | AD36: =AB36+AC36 -> 469.78 | AE36: =AD36 -> 469.78 | AF36: =AC36 -> 25.72 | AG36: =AE36+AF36 -> 495.5 | AH36: =AG36 -> 495.5 | AI36: =AF36 -> 25.72 | AJ36: =AH36+AI36 -> 521.22
B37: Year-end Carrying Value | E37: =E26-E31-E36 -> 587.46 | H37: =H26-H31-H36 -> 536.62 | K37: =K26-K31-K36 -> 428.85 | N37: =N26-N31-N36 -> 415.89 | Q37: =Q26-Q31-Q36 -> 844.16 | T37: =T26-T31-T36 -> 588.77 | W37: =W26-W31-W36 -> 475.29 | AA37: =AA26-AA31-AA36 -> 690.85502 | AD37: =AD26-AD31-AD36 -> 765.04743 | AG37: =AG26-AG31-AG36 -> 848.49359 | AJ37: =AJ26-AJ31-AJ36 -> 942.04096
B40: RIGHT-OF-USE ASSET | V40: DEPRECIATION & AMORTISATION EXPENSE
B41: (in ₹ Cr. unless stated otherwise) | V41: (in ₹ Cr. unless stated otherwise)
B42: Years | F42: =G42-1 -> 20 | G42: 21 | H42: =G42+1 -> 22 | I42: =H42+1 -> 23 | J42: =I42+1 -> 24 | K42: =J42+1 -> 25 | L42: =K42+1 -> 26 | M42: =L42+1 -> 27 | N42: =M42+1 -> 28 | O42: =N42+1 -> 29 | P42: =O42+1 -> 30 | V42: Years | Z42: =AA42-1 -> 20 | AA42: 21 | AB42: =AA42+1 -> 22 | AC42: =AB42+1 -> 23 | AD42: =AC42+1 -> 24 | AE42: =AD42+1 -> 25 | AF42: =AE42+1 -> 26 | AG42: =AF42+1 -> 27 | AH42: =AG42+1 -> 28 | AI42: =AH42+1 -> 29 | AJ42: =AI42+1 -> 30
B44: Balance at 1st April | F44: 871.12 | G44: =F47 -> 920.09 | H44: =G47 -> 845.55 | I44: =H47 -> 905.75 | J44: =I47 -> 1208.92 | K44: =J47 -> 1856.27 | L44: =K47 -> 1843.72 | M44: =L47 -> 2018.77 | N44: =M47 -> 2162.4989 | ... P44: =O47 -> 2481.3841 | V44: Depreciation of Property, Plant and Equipment | Z44: 532.43 | AA44: 544.45 | AB44: 546.29 | AC44: 551.5 | AD44: 483.64 | AE44: 617.08 | AF44: 809.32 | AG44: =Z16 -> 806.60043 | AH44: =AC16 -> 833.03141 | AI44: =AF16 -> 866.576 | AJ44: =AI16 -> 907.42249
B45: Net Additions | F45: =302.19+2.96-9.35-33.43 -> 262.37 | G45: =222.48+1.17-83.03 -> 140.62 | H45: =346.17-42.13-2.6 -> 301.44 | I45: =613.58-2.67-30.31 -> 580.6 | J45: =1011.35+34.4-51.71-0.57 -> 993.47 | K45: =439.68+0-58.34-0.19-8.21 -> 372.94 | L45: =607.89+21.59-53.89 -> 575.59 | M45: =M47-M44+M46 -> 639.99171 | N45: =N47-N44+N46 -> 685.55673 | O45: =O47-O44+O46 -> 734.36581 | P45: =P47-P44+P46 -> 786.64991 | V45: Depreciation of Right-of-Use assets (net) | Z45: 212.91 | AA45: 215.16 | AB45: 241.24 | AC45: 277.43 | AD45: 342.02 | AE45: 378.17 | AF45: 392.49 | AG45: =M46 -> 496.26283 | AH45: =N46 -> 531.59489 | AI45: =O46 -> 569.44246 | AJ45: =P46 -> 609.98464
B46: Depreciation | F46: 213.4 | G46: 215.16 | H46: 241.24 | I46: 277.43 | J46: 346.12 | K46: 385.49 | L46: 400.54 | M46: =M47*$M$50 -> 496.26283 | N46: =N47*$M$50 -> 531.59489 | O46: =O47*$M$50 -> 569.44246 | P46: =P47*$M$50 -> 609.98464 | V46: Amortisation of Other Intangible assets (net) | Z46: 35.16 | AA46: 31.66 | AB46: 28.83 | AC46: 29.09 | AD46: 27.34 | AE46: 31.09 | AF46: 27.04 | AG46: =Z31 -> 35.207858 | AH46: =AC31 -> 38.307387 | AI46: =AF31 -> 41.69399 | AJ46: =AI31 -> 45.393957
...

Sheet Ratio Analysis
G2: NSE: ASIANPAINT | BSE:500820
G3: 52-WEEK (HIGH: ₹ 2985.70| LOW: ₹ 2115.00 )
G4: 2649.4
G5: (as at 13 July 2026)
B6: FINANCIAL RATIOS
H8: Historical | S8: Forecasts
B9: Years | I9: =J9-1 -> 20 | J9: 21 | K9: =J9+1 -> 22 | L9: =K9+1 -> 23 | M9: =L9+1 -> 24 | N9: =M9+1 -> 25 | O9: =N9+1 -> 26 | P9: Trend | Q9: Median | R9: Mean | S9: =O9+1 -> 27 | T9: =S9+1 -> 28 | U9: =T9+1 -> 29 | V9: =U9+1 -> 30
B11: Year-end Share Price | I11: 1666.5 | J11: 2537.4 | K11: 3079.95 | L11: 2761.65 | M11: 2846.75 | N11: 2340.65 | O11: 2165.2 | Q11: =MEDIAN(I11:O11) -> 2537.4 | R11: =AVERAGE(I11:O11) -> 2485.4429 | S11: N/A | T11: N/A | U11: N/A | V11: N/A
B13: GROWTH ANALYSIS
B14: Revenue Growth % | I14: 0 | J14: =SOPL!J13/SOPL!I13-1 -> 0.074292288 | K14: =SOPL!K13/SOPL!J13-1 -> 0.34028285 | L14: =SOPL!L13/SOPL!K13-1 -> 0.18512278 | M14: =SOPL!M13/SOPL!L13-1 -> 0.029173127 | N14: =SOPL!N13/SOPL!M13-1 -> -0.044770308 | O14: =SOPL!O13/SOPL!N13-1 -> 0.049487961 | Q14: =MEDIAN(I14:O14) -> 0.049487961 | R14: =AVERAGE(I14:O14) -> 0.090512671 | S14: =SOPL!P13/SOPL!O13-1 -> 0.091370092 | T14: =SOPL!Q13/SOPL!P13-1 -> 0.091413824 | U14: =SOPL!R13/SOPL!Q13-1 -> 0.091451199 | V14: =SOPL!S13/SOPL!R13-1 -> 0.091483139
B15: Cost of Goods Sold (COGS) Growth % | I15: 0 | J15: =SOPL!J17/SOPL!I17-1 -> 0.062702377 | K15: =SOPL!K17/SOPL!J17-1 -> 0.512805 | L15: =SOPL!L17/SOPL!K17-1 -> 0.15604552 | M15: =SOPL!M17/SOPL!L17-1 -> -0.050400113 | N15: =SOPL!N17/SOPL!M17-1 -> -0.028592533 | O15: =SOPL!O17/SOPL!N17-1 -> 0.024902925 | Q15: =MEDIAN(I15:O15) -> 0.024902925 | R15: =AVERAGE(I15:O15) -> 0.096780453 | S15: =SOPL!P17/SOPL!O17-1 -> 0.12984109 | T15: =SOPL!Q17/SOPL!P17-1 -> 0.091413824 | U15: =SOPL!R17/SOPL!Q17-1 -> 0.091451199 | V15: =SOPL!S17/SOPL!R17-1 -> 0.091483139
B16: Earnings Before Interest, Tax, Depreciation & Amortisation (EBITDA) Growth % | I16: 0 | J16: =SOPL!J22/SOPL!I22-1 -> 0.15507335 | K16: =SOPL!K22/SOPL!J22-1 -> 0.0048404137 | L16: =SOPL!L22/SOPL!K22-1 -> 0.28217732 | M16: =SOPL!M22/SOPL!L22-1 -> 0.24473995 | N16: =SOPL!N22/SOPL!M22-1 -> -0.20477847 | O16: =SOPL!O22/SOPL!N22-1 -> 0.12781927 | Q16: =MEDIAN(I16:O16) -> 0.12781927 | R16: =AVERAGE(I16:O16) -> 0.087124548 | S16: =SOPL!P22/SOPL!O22-1 -> 0.063955242 | T16: =SOPL!Q22/SOPL!P22-1 -> 0.082109363 | U16: =SOPL!R22/SOPL!Q22-1 -> 0.081883121 | V16: =SOPL!S22/SOPL!R22-1 -> 0.081646083
B17: Earnings Before Interest & Tax (EBIT) Growth % | I17: 0 | J17: =SOPL!J24/SOPL!I24-1 -> 0.18499124 | K17: =SOPL!K24/SOPL!J24-1 -> -2.7476428e-05 | L17: =SOPL!L24/SOPL!K24-1 -> 0.3253848 | M17: =SOPL!M24/SOPL!L24-1 -> 0.28188587 | N17: =SOPL!N24/SOPL!M24-1 -> -0.25168128 | O17: =SOPL!O24/SOPL!N24-1 -> 0.11497385 | Q17: =MEDIAN(I17:O17) -> 0.11497385 | R17: =AVERAGE(I17:O17) -> 0.093646714 | S17: =SOPL!P24/SOPL!O24-1 -> 0.059007677 | T17: =SOPL!Q24/SOPL!P24-1 -> 0.088973973 | U17: =SOPL!R24/SOPL!Q24-1 -> 0.087499449 | V17: =SOPL!S24/SOPL!R24-1 -> 0.086226175
B18: Earnings Before Tax (EBT) Growth % | I18: 0 | J18: =SOPL!J28/SOPL!I28-1 -> 0.18446941 | K18: =SOPL!K28/SOPL!J28-1 -> -0.027095845 | L18: =SOPL!L28/SOPL!K28-1 -> 0.3584552 | M18: =SOPL!M28/SOPL!L28-1 -> 0.29161357 | N18: =SOPL!N28/SOPL!M28-1 -> -0.30549405 | O18: =SOPL!O28/SOPL!N28-1 -> 0.17643693 | Q18: =MEDIAN(I18:O18) -> 0.17643693 | R18: =AVERAGE(I18:O18) -> 0.096912173 | S18: =SOPL!P28/SOPL!O28-1 -> 0.087562937 | T18: =SOPL!Q28/SOPL!P28-1 -> 0.089875609 | U18: =SOPL!R28/SOPL!Q28-1 -> 0.088394411 | V18: =SOPL!S28/SOPL!R28-1 -> 0.087118793
B19: Profit After Tax (PAT) Growth % | I19: 0 | J19: =SOPL!J31/SOPL!I31-1 -> 0.15592299 | K19: =SOPL!K31/SOPL!J31-1 -> -0.038026039 | L19: =SOPL!L31/SOPL!K31-1 -> 0.35999624 | M19: =SOPL!M31/SOPL!L31-1 -> 0.3247325 | N19: =SOPL!N31/SOPL!M31-1 -> -0.33250865 | O19: =SOPL!O31/SOPL!N31-1 -> 0.18464516 | Q19: =MEDIAN(I19:O19) -> 0.15592299 | R19: =AVERAGE(I19:O19) -> 0.093537457 | S19: =SOPL!P31/SOPL!O31-1 -> 0.087562937 | T19: =SOPL!Q31/SOPL!P31-1 -> 0.089875609 | U19: =SOPL!R31/SOPL!Q31-1 -> 0.088394411 | V19: =SOPL!S31/SOPL!R31-1 -> 0.087118793
B20: Earnings Per Share (EPS) Growth % | I20: 0 | J20: =SOPL!J34/SOPL!I34-1 -> 0.1606383 | K20: =SOPL!K34/SOPL!J34-1 -> -0.034830431 | L20: =SOPL!L34/SOPL!K34-1 -> 0.3558088 | M20: =SOPL!M34/SOPL!L34-1 -> 0.32967546 | N20: =SOPL!N34/SOPL!M34-1 -> -0.32835821 | O20: =SOPL!O34/SOPL!N34-1 -> 0.17960784 | Q20: =MEDIAN(I20:O20) -> 0.1606383 | R20: =AVERAGE(I20:O20) -> 0.094648823 | S20: =SOPL!P34/SOPL!O34-1 -> 0.087581056 | T20: =SOPL!Q34/SOPL!P34-1 -> 0.089875609 | U20: =SOPL!R34/SOPL!Q34-1 -> 0.088394411 | V20: =SOPL!S34/SOPL!R34-1 -> 0.087118793
B21: Dividend Growth % | I21: 0 | J21: =SOPL!J35/SOPL!I35-1 -> 0.48749826 | K21: =SOPL!K35/SOPL!J35-1 -> 0.072720583 | L21: =SOPL!L35/SOPL!K35-1 -> 0.37872683 | M21: =SOPL!M35/SOPL!L35-1 -> 0.26136525 | N21: =SOPL!N35/SOPL!M35-1 -> -0.25525573 | O21: =SOPL!O35/SOPL!N35-1 -> 0.10886956 | Q21: =MEDIAN(I21:O21) -> 0.10886956 | R21: =AVERAGE(I21:O21) -> 0.15056068 | S21: =SOPL!P35/SOPL!O35-1 -> 0.081453509 | T21: =SOPL!Q35/SOPL!P35-1 -> 0.089875609 | U21: =SOPL!R35/SOPL!Q35-1 -> 0.088394411 | V21: =SOPL!S35/SOPL!R35-1 -> 0.087118793
B23: LIQUIDITY RATIOS
B24: Current Ratio | I24: ='SOFP '!I33/('SOFP '!I61-'SOFP '!I60) -> 1.8046463 | J24: ='SOFP '!J33/('SOFP '!J61-'SOFP '!J60) -> 2.0718978 | K24: ='SOFP '!K33/('SOFP '!K61-'SOFP '!K60) -> 2.0364201 | L24: ='SOFP '!L33/('SOFP '!L61-'SOFP '!L60) -> 2.1384696 | M24: ='SOFP '!M33/('SOFP '!M61-'SOFP '!M60) -> 2.0931151 | N24: ='SOFP '!N33/('SOFP '!N61-'SOFP '!N60) -> 2.1199401 | O24: ='SOFP '!O33/('SOFP '!O61-'SOFP '!O60) -> 2.2534995 | Q24: =MEDIAN(I24:O24) -> 2.0931151 | R24: =AVERAGE(I24:O24) -> 2.0739983 | S24: ='SOFP '!P33/('SOFP '!P61-'SOFP '!P60) -> 2.2681859 | T24: ='SOFP '!Q33/('SOFP '!Q61-'SOFP '!Q60) -> 2.3233659 | U24: ='SOFP '!R33/('SOFP '!R61-'SOFP '!R60) -> 2.3716164 | V24: ='SOFP '!S33/('SOFP '!S61-'SOFP '!S60) -> 2.4140517
B25: Quick Ratio | I25: =('SOFP '!I33-'SOFP '!I25-'SOFP '!I32)/('SOFP '!I61-'SOFP '!I60) -> 0.99431235 | J25: =('SOFP '!J33-'SOFP '!J25-'SOFP '!J32)/('SOFP '!J61-'SOFP '!J60) -> 1.4151651 | K25: =('SOFP '!K33-'SOFP '!K25-'SOFP '!K32)/('SOFP '!K61-'SOFP '!K60) -> 1.2083885 | L25: =('SOFP '!L33-'SOFP '!L25-'SOFP '!L32)/('SOFP '!L61-'SOFP '!L60) -> 1.335256 | M25: =('SOFP '!M33-'SOFP '!M25-'SOFP '!M32)/('SOFP '!M61-'SOFP '!M60) -> 1.3861335 | N25: =('SOFP '!N33-'SOFP '!N25-'SOFP '!N32)/('SOFP '!N61-'SOFP '!N60) -> 1.281621 | O25: =('SOFP '!O33-'SOFP '!O25-'SOFP '!O32)/('SOFP '!O61-'SOFP '!O60) -> 1.6122494 | Q25: =MEDIAN(I25:O25) -> 1.335256 | R25: =AVERAGE(I25:O25) -> 1.319018 | S25: =('SOFP '!P33-'SOFP '!P25-'SOFP '!P32)/('SOFP '!P61-'SOFP '!P60) -> 1.5946116 | T25: =('SOFP '!Q33-'SOFP '!Q25-'SOFP '!Q32)/('SOFP '!Q61-'SOFP '!Q60) -> 1.6453153 | U25: =('SOFP '!R33-'SOFP '!R25-'SOFP '!R32)/('SOFP '!R61-'SOFP '!R60) -> 1.689595 | V25: =('SOFP '!S33-'SOFP '!S25-'SOFP '!S32)/('SOFP '!S61-'SOFP '!S60) -> 1.728584
B27: SOLVENCY RATIOS
B28: Financial Gearing Ratio | G28: (D/E) | I28: =('SOFP '!I46+'SOFP '!I47)/'SOFP '!I41 -> 0.057773677 | J28: =('SOFP '!J46+'SOFP '!J47)/'SOFP '!J41 -> 0.043531897 | K28: =('SOFP '!K46+'SOFP '!K47)/'SOFP '!K41 -> 0.045278254 | L28: =('SOFP '!L46+'SOFP '!L47)/'SOFP '!L41 -> 0.048953872 | M28: =('SOFP '!M46+'SOFP '!M47)/'SOFP '!M41 -> 0.059189093 | N28: =('SOFP '!N46+'SOFP '!N47)/'SOFP '!N41 -> 0.068942447 | O28: =('SOFP '!O46+'SOFP '!O47)/'SOFP '!O41 -> 0.11601691 | Q28: =MEDIAN(I28:O28) -> 0.057773677 | R28: =AVERAGE(I28:O28) -> 0.062812308 | S28: =('SOFP '!P46+'SOFP '!P47)/'SOFP '!P41 -> 0.12127383 | T28: =('SOFP '!Q46+'SOFP '!Q47)/'SOFP '!Q41 -> 0.12764326 | U28: =('SOFP '!R46+'SOFP '!R47)/'SOFP '!R41 -> 0.13461807 | V28: =('SOFP '!S46+'SOFP '!S47)/'SOFP '!S41 -> 0.1422629
B29: Interest Cover | I29: =SOPL!I24/SOPL!I27 -> 36.016613 | J29: =SOPL!J24/SOPL!J27 -> 47.663211 | K29: =SOPL!K24/SOPL!K27 -> 45.773609 | L29: =SOPL!L24/SOPL!L27 -> 40.071305 | M29: =SOPL!M24/SOPL!M27 -> 36.164839 | N29: =SOPL!N24/SOPL!N27 -> 24.458109 | O29: =SOPL!O24/SOPL!O27 -> 31.681439 | Q29: =MEDIAN(I29:O29) -> 36.164839 | R29: =AVERAGE(I29:O29) -> 37.404161 | S29: =SOPL!P24/SOPL!P27 -> 31.242825 | T29: =SOPL!Q24/SOPL!Q27 -> 31.682109 | U29: =SOPL!R24/SOPL!R27 -> 32.084067 | V29: =SOPL!S24/SOPL!S27 -> 32.453083
B31: PERFORMANCE RATIOS
B32: Gross Profit Margin % | I32: =SOPL!I18/SOPL!I13 -> 0.43677605 | J32: =SOPL!J18/SOPL!J13 -> 0.44285235 | K32: =SOPL!K18/SOPL!K13 -> 0.37113591 | L32: =SOPL!L18/SOPL!L13 -> 0.38656524 | M32: =SOPL!M18/SOPL!M13 -> 0.43399457 | N32: =SOPL!N18/SOPL!N13 -> 0.4244087 | O32: =SOPL!O18/SOPL!O13 -> 0.43789235 | Q32: =MEDIAN(I32:O32) -> 0.43399457 | R32: =AVERAGE(I32:O32) -> 0.41908931 | S32: =SOPL!P18/SOPL!P13 -> 0.41807795 | T32: =SOPL!Q18/SOPL!Q13 -> 0.41807795 | U32: =SOPL!R18/SOPL!R13 -> 0.41807795 | V32: =SOPL!S18/SOPL!S13 -> 0.41807795
B33: Earnings Before Interest, Tax, Depreciation & Amortisation (EBITDA) Margin % | I33: =SOPL!I22/SOPL!I13 -> 0.22097 | J33: =SOPL!J22/SOPL!J13 -> 0.23758577 | K33: =SOPL!K22/SOPL!K13 -> 0.17812344 | L33: =SOPL!L22/SOPL!L13 -> 0.19271069 | M33: =SOPL!M22/SOPL!M13 -> 0.23307516 | N33: =SOPL!N22/SOPL!N13 -> 0.19403332 | O33: =SOPL!O22/SOPL!O13 -> 0.20851551 | Q33: =MEDIAN(I33:O33) -> 0.20851551 | R33: =AVERAGE(I33:O33) -> 0.2092877 | S33: =SOPL!P22/SOPL!P13 -> 0.20327767 | T33: =SOPL!Q22/SOPL!Q13 -> 0.2015447 | U33: =SOPL!R22/SOPL!R13 -> 0.19977788 | V33: =SOPL!S22/SOPL!S13 -> 0.19797737
